Traceback (most recent call last):
  File "/home/tools/generate_diff.py", line 8, in <module>
    generate_diff()
  File "/home/tools/generate_diff.py", line 4, in generate_diff
    subprocess.run('git --no-pager diff > final_patch.diff', cwd='/repo', shell=True, check=True, capture_output=True)
  File "/usr/local/lib/python3.10/subprocess.py", line 526, in run
    raise CalledProcessError(retcode, process.args,
subprocess.CalledProcessError: Command 'git --no-pager diff > final_patch.diff' returned non-zero exit status 129.
The command execution failed, so I have reverted it back to the previous state, which is the environment before running this command.