#0 building with "default" instance using docker driver

#1 [internal] load build definition from Dockerfile
#1 transferring dockerfile: 2.25kB 0.0s done
#1 DONE 0.0s

#2 [internal] load metadata for docker.io/library/python:3.10
#2 DONE 0.0s

#3 [internal] load .dockerignore
#3 transferring context: 2B done
#3 DONE 0.0s

#4 [ 1/11] FROM docker.io/library/python:3.10
#4 DONE 0.0s

#5 [internal] load build context
#5 transferring context: 186B done
#5 DONE 0.0s

#6 [ 4/11] RUN mkdir -p ~/.pip && touch ~/.pip/pip.conf &&     echo "[global]" >> ~/.pip/pip.conf && echo "index-url=http://simple/" >> ~/.pip/pip.conf && echo "[install]" >> ~/.pip/pip.conf && echo "trusted-host=pypi..org" >> ~/.pip/pip.conf &&     apt-get update && apt-get install -y curl &&     curl -sSL https://install.python-poetry.org | python -
#6 CACHED

#7 [ 5/11] RUN pip install pytest pytest-xdist &&     pip install pipdeptree &&     git clone https://github.com/DataformerAI/dataformer.git &&     mkdir /repo &&     git config --global --add safe.directory /repo &&     cp -r /dataformer/. /repo && rm -rf /dataformer/ &&     rm -rf /dataformer &&     cd /repo && git checkout 0cf88cc22a20a6d5d115773ae9aac8970d7812e3 &&     pip install pydantic==2.10.4 &&     pip install tiktoken==0.8.0 &&     pip install aiohttp==3.11.11 &&     pip install python-dotenv==1.0.1 &&     pip install pytest==8.3.4 &&     pip install ruff==0.4.5 &&     pip install pre-commit==4.0.1 &&     pip install black==24.4.2 &&     pip install pytest-asyncio==0.25.2 &&     pip install nest-asyncio==1.6.0 &&     pip install pytest-timeout==2.3.1 &&     pip install pytest-codspeed==3.1.1 &&     pip install openai==1.59.5
#7 CACHED

#8 [ 2/11] COPY search_patch /search_patch
#8 CACHED

#9 [ 3/11] COPY code_edit.py /code_edit.py
#9 CACHED

#10 [ 7/11] RUN python /code_edit.py -t "/search_patch/1.patch"
#10 CACHED

#11 [ 8/11] RUN pip install pytest-mock==3.14.0
#11 CACHED

#12 [ 6/11] RUN pip install jinja2==3.1.5 &&     pip install datasets==3.2.0 &&     python /code_edit.py -t "/search_patch/0.patch"
#12 CACHED

#13 [ 9/11] RUN python /code_edit.py -t "/search_patch/2.patch"
#13 CACHED

#14 [10/11] RUN cd /repo && pytest --collect-only -q
#14 1.071 /usr/local/lib/python3.10/site-packages/pytest_asyncio/plugin.py:207: PytestDeprecationWarning: The configuration option "asyncio_default_fixture_loop_scope" is unset.
#14 1.071 The event loop scope for asynchronous fixtures will default to the fixture caching scope. Future versions of pytest-asyncio will default the loop scope for asynchronous fixtures to function scope. Set the default fixture loop scope explicitly in order to avoid unexpected behavior in the future. Valid fixture loop scopes are: "function", "class", "module", "package", "session"
#14 1.071 
#14 1.071   warnings.warn(PytestDeprecationWarning(_DEFAULT_FIXTURE_LOOP_SCOPE_UNSET))
#14 9.899 tests/test_all_api_providers_in_request_list.py::test_all_api_providers
#14 9.899 tests/test_cache_vars.py::test_cache_vars
#14 9.899 tests/test_caching_requests.py::test_caching_requests
#14 9.899 tests/test_complexity_scorer.py::test_complexity_scorer
#14 9.899 tests/test_deita.py::test_deita
#14 9.899 tests/test_embeddings.py::test_embedding_generation
#14 9.899 tests/test_eval_quality.py::test_evol_quality
#14 9.899 tests/test_evol_instruct.py::test_evol_instruct
#14 9.899 tests/test_inference_compute_tests.py::test_cot
#14 9.899 tests/test_inference_compute_tests.py::test_self_consistency
#14 9.899 tests/test_inference_compute_tests.py::test_pvg
#14 9.899 tests/test_inference_compute_tests.py::test_rto
#14 9.899 tests/test_inference_compute_tests.py::test_inference_compute_tests
#14 9.899 tests/test_llm_chat_generation.py::test_llm_generate_proper_response
#14 9.899 tests/test_llm_text_generation.py::test_llm_generate_proper_response
#14 9.899 tests/test_quality_scorer.py::test_quality_scorer
#14 9.899 tests/test_sampling_params.py::test_sampling_parameters
#14 9.899 tests/test_task_id_generator.py::test_task_id_generator
#14 9.899 tests/test_various_limits_request_list_formation.py::test_various_limits_and_request_lists
#14 9.899 
#14 9.899 =============================== warnings summary ===============================
#14 9.899 ../usr/local/lib/python3.10/site-packages/_pytest/config/__init__.py:1441
#14 9.899   /usr/local/lib/python3.10/site-packages/_pytest/config/__init__.py:1441: PytestConfigWarning: Unknown config option: python_paths
#14 9.899   
#14 9.899     self._warn_or_fail_if_strict(f"Unknown config option: {key}\n")
#14 9.899 
#14 9.899 -- Docs: https://docs.pytest.org/en/stable/how-to/capture-warnings.html
#14 9.899 19 tests collected in 8.79s
#14 DONE 10.5s

#15 exporting to image
#15 exporting layers 0.0s done
#15 writing image sha256:d1ca9cacf25af3abfc1246dc3fda6ffae52931a67427f2c93a989a5bacee1197 done
#15 naming to docker.io/library/tmp:tmp done
#15 DONE 0.1s
